



date: Wed Oct  4 03:53:04 PM EDT 2023
**** JHPCE info ****
User: rmiller
Job id: 300705
Job name: r2python
Hostname: 
Task id: 3
date: Wed Oct  4 03:53:04 PM EDT 2023
**** JHPCE info ****
User: rmiller
Job id: 300704
Job name: r2python
Hostname: 
Task id: 2
Loading LIBD module for samui/1.0.0-next.45
Loading LIBD module for samui/1.0.0-next.45
/jhpce/shared/libd/core/samui/1.0.0-next.45/samui_env/lib/python3.10/site-packages/pydantic/_internal/_config.py:261: UserWarning: Valid config keys have changed in V2:
* 'allow_mutation' has been removed
  warnings.warn(message, UserWarning)
/jhpce/shared/libd/core/samui/1.0.0-next.45/samui_env/lib/python3.10/site-packages/pydantic/_internal/_config.py:261: UserWarning: Valid config keys have changed in V2:
* 'allow_mutation' has been removed
  warnings.warn(message, UserWarning)
/jhpce/shared/libd/core/samui/1.0.0-next.45/samui_env/lib/python3.10/site-packages/openpyxl/worksheet/_reader.py:329: UserWarning: Unknown extension is not supported and will be removed
  warn(msg)
/jhpce/shared/libd/core/samui/1.0.0-next.45/samui_env/lib/python3.10/site-packages/openpyxl/worksheet/_reader.py:329: UserWarning: Unknown extension is not supported and will be removed
  warn(msg)
Traceback (most recent call last):
Traceback (most recent call last):
  File "/jhpce/shared/libd/core/samui/1.0.0-next.45/samui_env/lib/python3.10/site-packages/pandas/core/indexes/base.py", line 3653, in get_loc
  File "/jhpce/shared/libd/core/samui/1.0.0-next.45/samui_env/lib/python3.10/site-packages/pandas/core/indexes/base.py", line 3653, in get_loc
    return self._engine.get_loc(casted_key)
  File "pandas/_libs/index.pyx", line 147, in pandas._libs.index.IndexEngine.get_loc
    return self._engine.get_loc(casted_key)
  File "pandas/_libs/index.pyx", line 147, in pandas._libs.index.IndexEngine.get_loc
  File "pandas/_libs/index.pyx", line 176, in pandas._libs.index.IndexEngine.get_loc
  File "pandas/_libs/index.pyx", line 176, in pandas._libs.index.IndexEngine.get_loc
  File "pandas/_libs/hashtable_class_helper.pxi", line 7080, in pandas._libs.hashtable.PyObjectHashTable.get_item
  File "pandas/_libs/hashtable_class_helper.pxi", line 7080, in pandas._libs.hashtable.PyObjectHashTable.get_item
  File "pandas/_libs/hashtable_class_helper.pxi", line 7088, in pandas._libs.hashtable.PyObjectHashTable.get_item
  File "pandas/_libs/hashtable_class_helper.pxi", line 7088, in pandas._libs.hashtable.PyObjectHashTable.get_item
KeyError: 'Slide SN #'

The above exception was the direct cause of the following exception:

Traceback (most recent call last):
  File "/dcs04/lieber/marmaypag/spatialdACC_LIBD4125/spatialdACC/code/09_samui/02_loopy-if.py", line 73, in <module>
    sample_ids_img = sample_info['Slide SN #'] + '_' + sample_info['Array #']
  File "/jhpce/shared/libd/core/samui/1.0.0-next.45/samui_env/lib/python3.10/site-packages/pandas/core/frame.py", line 3761, in __getitem__
KeyError: 'Slide SN #'

The above exception was the direct cause of the following exception:

Traceback (most recent call last):
  File "/dcs04/lieber/marmaypag/spatialdACC_LIBD4125/spatialdACC/code/09_samui/02_loopy-if.py", line 73, in <module>
    sample_ids_img = sample_info['Slide SN #'] + '_' + sample_info['Array #']
  File "/jhpce/shared/libd/core/samui/1.0.0-next.45/samui_env/lib/python3.10/site-packages/pandas/core/frame.py", line 3761, in __getitem__
    indexer = self.columns.get_loc(key)
    indexer = self.columns.get_loc(key)
  File "/jhpce/shared/libd/core/samui/1.0.0-next.45/samui_env/lib/python3.10/site-packages/pandas/core/indexes/base.py", line 3655, in get_loc
  File "/jhpce/shared/libd/core/samui/1.0.0-next.45/samui_env/lib/python3.10/site-packages/pandas/core/indexes/base.py", line 3655, in get_loc
    raise KeyError(key) from err
KeyError: 'Slide SN #'
    raise KeyError(key) from err
KeyError: 'Slide SN #'
**** Job ends ****
**** Job ends ****
Wed Oct  4 03:53:17 PM EDT 2023
Wed Oct  4 03:53:19 PM EDT 2023




